Workbook
Name B.E: #REF!
Name B_Capex__Infrastructure: [2]Assumptions!$Q$19
Name B_Capping_Cost_per_tonne: [2]Assumptions!$T$19
Name B_Cell_Cost: [2]Assumptions!$S$19
Name B_Change_in_Working_Capital: [2]DCF!$E$269:$U$269
Name B_Construction_start_date: [2]Assumptions!$F$19
Name B_Depletion_Charge: [2]DCF!$E$165:$U$165
Name B_End_of_Life_Cost: [2]Assumptions!$Z$19
Name B_Fixed_Opex: [2]Assumptions!$P$19
Name B_Leachate_Logistics_and_Freight_Cost: [2]Assumptions!$W$19
Name B_Market_Share_in_Silverberry_Closes_Scenario: [2]Assumptions!$K$19
Name B_Market_Share_with_Competition: [2]Assumptions!$J$19
Name B_Market_share_without_Competition: [2]Assumptions!$I$19
Name B_Max_Throughput: [2]DCF!$E$127:$U$127
Name B_Op_days_before_Competition: [2]Assumptions!$U$19
Name B_Op_days_with_Competition: [2]Assumptions!$V$19
Name B_Opex_Costs: [2]DCF!$E$360:$U$360
Name B_Rate___Increase_in_Silverberry_Close_Scenario___No_Competition: [2]Assumptions!$O$19
Name B_Rate___Increase_in_Silverberry_Close_Scenario_Competition: [2]Assumptions!$N$19
Name B_Rate___Increase_with_Competition: [2]Assumptions!$M$19
Name B_Rate___Increase_without_Competition: [2]Assumptions!$L$19
Name B_Remediation: [2]Assumptions!$Y$19
Name B_Remediation_Year: [2]Assumptions!$X$19
Name B_Total_Waste_Revenue: [2]DCF!$E$255:$U$255
Name base: [3]Model!#REF!
Name BASE_CONDENSATE_VOLUME: '[4]C5+'!$C$17
Name BASE_SW_VOLUME: [4]SW!$E$17
Name basediff: [3]Assumptions!#REF!
Name basefreight: [3]Assumptions!#REF!
Name basesales: [3]Assumptions!#REF!
Name basis: [3]Assumptions!#REF!
Name BlackPEARLHeavyOil: '[5]BLEND MODEL'!$D$22
Name BlackSPURHeavyOil: '[5]BLEND MODEL'!#REF!
Name BlendDensity: '[5]BLEND MODEL'!$I$40
Name BlendSulphurPercent: '[5]BLEND MODEL'!$I$41
Name BOY: '[6]Inputs & Assumptions'!#REF!
Name brown: [3]Model!#REF!
Name browndiff: [3]Assumptions!#REF!
Name brownfreight: [3]Assumptions!#REF!
Name BrownIRR: [3]DCF!#REF!
Name brownprod: [3]Model!$A$10:$IV$10,[3]Model!#REF!
Name brownsales: [3]Assumptions!#REF!
Name Budget: [7]Input!$B$11
Name ButaneInjected: '[5]BLEND MODEL'!$H$22
Name Calendar_Year: '[2]Fixed Assumptions'!$E$1:$AF$1
Name capex: [8]Assumptions!$C$29
Name Capex_Type: [9]Tables!$B$4:$B$17
Name case: [3]Model!#REF!
Name Current_Forecast: [10]Inputs!$B$3
Name Current_Period: [7]Input!$B$5
Name Current_QTD: [10]Inputs!$B$9
Name Current_YTD: [7]Input!$B$7
Name days: [8]Assumptions!$C$5
Name DCFIRR: [3]DCF!$F$34
Name DEEMED_BUTANE: '[4]C5+'!$K$40
Name Depre: [8]Assumptions!$C$7
Name deptid: '[11]Inputs & Assumptions'!$B$4
Name Discount_Factor: '[2]Fixed Assumptions'!$E$4:$AF$4
Name discount_rate: #REF!
Name Division: [9]Tables!$H$4:$H$15

Sheet Inputs
C3: INPUTS
B4: Pricing Month | C4: 45413
B5: Producer Raw Crude Volume | C5: 21147 | D5: M3/M
B6: Producer Raw Crude TAN | C6: 0.65 | D6: mgOH
B7: FSK Condensate Density | C7: 660 | D7: KG/M3
B8: FSK Condensate Sulphur | C8: 0.00015 | D8: %Swt
B9: FSK Condensate Truck Unload | C9: 8.5 | D9: CAD/M3
B10: FSK Condensate Transport (UtikumaNorth) | C10: ='Spur-Netback'!I9 -> 32.586207 | D10: CAD/M3
B11: FSK Condensate Transport (Utikuma/Nipisi-South) | C11: ='Spur-Netback'!I11 -> 29.689655 | D11: CAD/M3
B12: FSK Condensate Transport (Mitsue) | C12: ='Spur-Netback'!I12 -> 25.344828 | D12: CAD/M3
B13: CRW Condensate Density | C13: 730 | D13: KG/M3
B14: RP2 Condensate Density | C14: 737 | D14: KG/M3
B15: C4 Landed Price (not included Transportation) | C15: ='UtikuSouthTT DilFee Nipisi'!B10 -> 0.475 | D15: % WTI
B16: Spur Raw Crude Density | C16: 965 | D16: KG/M3
B17: Spur Historical Monthly Blend Density Target (Actual Physical) | C17: =_xlfn.XLOOKUP($C$4,MonthlyData!$B:$B,MonthlyData!$CB:$CB) -> 924.2 | D17: KG/M3
B18: Spur Monthly Paper Blend Density (350cSt) | C18: =_xlfn.XLOOKUP($C$4,MonthlyData!$B:$B,MonthlyData!$CC:$CC) -> 924.4 | D18: KG/M3
B19: Utikuma North Terminal Fee | C19: 5.25 | D19: CAD/M3
B20: Utikuma South Terminal Fee | C20: 4.7 | D20: CAD/M3
B21: Utikuma North Terminal Pembina Power Surcharge | C21: 0.1 | D21: CAD/M3
B22: Utikuma Diluent Sharing | C22: 0.9 | D22: %
B23: Mitsue Diluent Sharing | C23: 0.85 | D23: %
B24: Producer | C24: Spur
B25: Butane Injection | C25: 0.0319 | D25: C4/Raw %
B26: Nipisi Pipeline L/A | C26: 0.002
B27: Rainbow Pipeline L/A | C27: 0.002
B28: Utikuma North TT Location Factor | C28: 1.1
B30: Customer Producers
B31: Spur
B32: Tamarack
B33: Obsidian
B34: Baytex
B35: Headwater
B37: Month of the Year
B38: January
B39: February
B40: March
B41: April
B42: May
... B49: December
B51: Pricing Month | C51: 45200 | D51: 45231 | E51: 45261 | F51: 45292 | G51: 45323 | H51: 45352 | I51: 45383 | J51: 45413 | K51: 45444 | L51: 45474 | M51: 45505 | N51: 45536 | O51: 45566 | P51: 45597 | Q51: 45627 | R51: 45658 | S51: 45689 | T51: 45717 | U51: 45748 | V51: 45778

Sheet Spur-Netback
B2: Butane Trucking (KeyeraFortSask) | C2: Length (hrs) | D2: Round Trip | E2: Loading & Unloading | F2: Total Truck Hours | G2: Truck Rate (CAD/HR) | H2: Truck Volume (M3 Raw/Load) | I2: Trucking Cost (CAD/M3 C4)
B3: Utikuma North Truck Terminal (Nipisi P/L) | C3: 3.5 | D3: =C3*2 -> 7 | E3: =IF(C3>0, 2, 0) -> 2 | F3: =E3+D3 -> 9 | G3: 210 | H3: 62 | I3: =(F3*G3)/H3 -> 30.483871
B4: Nipisi South Truck Terminal (Nipisi P/L) | C4: 3.1 | D4: =C4*2 -> 6.2 | E4: =IF(C4>0, 2, 0) -> 2 | F4: =E4+D4 -> 8.2 | G4: =$G$15 -> 210 | H4: =H$3 -> 62 | I4: =(F4*G4)/H4 -> 27.774194
B5: Utikuma South Truck Terminal (Nipisi P/L) | C5: 3.1 | D5: =C5*2 -> 6.2 | E5: =IF(C5>0, 2, 0) -> 2 | F5: =E5+D5 -> 8.2 | G5: =$G$15 -> 210 | H5: =H$3 -> 62 | I5: =(F5*G5)/H5 -> 27.774194
B6: Mitsue Truck Terminal (Nipisi P/L) | C6: 2.5 | D6: =C6*2 -> 5 | E6: =IF(C6>0, 2, 0) -> 2 | F6: =E6+D6 -> 7 | G6: =$G$15 -> 210 | H6: =H$3 -> 62 | I6: =(F6*G6)/H6 -> 23.709677
B8: Condensate Trucking (KeyeraFortSask) | C8: Length (hrs) | D8: Round Trip | E8: Loading & Unloading | F8: Total Truck Hours | G8: Truck Rate (CAD/HR) | H8: Truck Volume (M3 Raw/Load) | I8: Trucking Cost (CAD/M3 C5+)
B9: Utikuma North Truck Terminal (Nipisi P/L) | C9: 3.5 | D9: =C9*2 -> 7 | E9: =IF(C9>0, 2, 0) -> 2 | F9: =E9+D9 -> 9 | G9: 210 | H9: 58 | I9: =(F9*G9)/H9 -> 32.586207
B10: Nipisi South Truck Terminal (Nipisi P/L) | C10: 3.1 | D10: =C10*2 -> 6.2 | E10: =IF(C10>0, 2, 0) -> 2 | F10: =E10+D10 -> 8.2 | G10: =$G$15 -> 210 | H10: =H$9 -> 58 | I10: =(F10*G10)/H10 -> 29.689655
B11: Utikuma South Truck Terminal (Nipisi P/L) | C11: 3.1 | D11: =C11*2 -> 6.2 | E11: =IF(C11>0, 2, 0) -> 2 | F11: =E11+D11 -> 8.2 | G11: =$G$15 -> 210 | H11: =H$9 -> 58 | I11: =(F11*G11)/H11 -> 29.689655
B12: Mitsue Truck Terminal (Nipisi P/L) | C12: 2.5 | D12: =C12*2 -> 5 | E12: =IF(C12>0, 2, 0) -> 2 | F12: =E12+D12 -> 7 | G12: =$G$15 -> 210 | H12: =H$9 -> 58 | I12: =(F12*G12)/H12 -> 25.344828
B14: Spur Raw Crude (Clean Only) Trucking (NipisiNorthHwy88) | C14: Length (hrs) | D14: Round Trip | E14: Loading & Unloading | F14: Total Truck Hours | G14: Truck Rate (CAD/HR) | H14: Truck Volume (M3 Raw/Load) | I14: Trucking Cost (CAD/M3 Raw) | W14: CHV Stream Blended Density Historicals | X14: Jan | Y14: Feb | Z14: Mar | AA14: Apr | AB14: May | AC14: June | AD14: July | AE14: Aug | AF14: Sept | AG14: Oct | AH14: Nov | AI14: Dec
B15: Nipisi North Truck Terminal (Rainbow P/L) | C15: 0 | D15: =C15*2 -> 0 | E15: 2 | F15: =E15+D15 -> 2 | G15: 210 | H15: 35 | I15: =(F15*G15)/H15 -> 12 | W15: 2023 CHV Blended Density | X15: 923.8 | Y15: 924.8 | Z15: 927.9 | AA15: 922 | AB15: 922.4 | AC15: 919.2 | AD15: 927 | AE15: 929.4 | AF15: 936.5 | AG15: 936.3 | AH15: 925.9 | AI15: 923.5
B16: Utikuma North Truck Terminal (Nipisi P/L) | C16: 0.1 | D16: =C16*2 -> 0.2 | E16: =IF(C16>0, 2, 0) -> 2 | F16: =E16+D16 -> 2.2 | G16: =$G$15 -> 210 | H16: 35 | I16: =(F16*G16)/H16 -> 13.2
B17: Nipisi South Truck Terminal (Nipisi P/L) | C17: 0.4 | D17: =C17*2 -> 0.8 | E17: =IF(C17>0, 2, 0) -> 2 | F17: =E17+D17 -> 2.8 | G17: =$G$15 -> 210 | H17: 35 | I17: =(F17*G17)/H17 -> 16.8 | W17: 2024 CHV Blended Density | X17: 926.4 | Y17: 920.1 | Z17: 920.2 | AA17: 921.2 | AB17: 924.1 | AC17: 924.6 | AD17: 931.3 | AE17: 932.9 | AF17: 934 | AG17: 934.4 | AH17: 930.6 | AI17: 925.3
B18: Utikuma South Truck Terminal (Nipisi P/L) | C18: 0.4 | D18: =C18*2 -> 0.8 | E18: =IF(C18>0, 2, 0) -> 2 | F18: =E18+D18 -> 2.8 | G18: =$G$15 -> 210 | H18: 35 | I18: =(F18*G18)/H18 -> 16.8
B19: Mitsue Truck Terminal (Nipisi P/L) | C19: 1 | D19: =C19*2 -> 2 | E19: =IF(C19>0, 2, 0) -> 2 | F19: =E19+D19 -> 4 | G19: =$G$15 -> 210 | H19: 35 | I19: =(F19*G19)/H19 -> 24 | W19: 2025 CWH Blended Density | X19: 921.6 | Y19: 921.9 | Z19: 920.6 | AA19: 921.6 | AB19: 922.8 | AC19: 927.1
B20: Spur MH Battery (Rainbow P/L) | C20: 1.8 | D20: =C20*2 -> 3.6 | E20: =IF(C20>0, 2, 0) -> 2 | F20: =E20+D20 -> 5.6 | G20: =$G$15 -> 210 | H20: 35 | I20: =(F20*G20)/H20 -> 33.6
B21: Gibsons Edmonton (CHV Pricing) | C21: 4.4 | D21: =C21*2 -> 8.8 | E21: =IF(C21>0, 2, 0) -> 2 | F21: =E21+D21 -> 10.8 | G21: =$G$15 -> 210 | H21: 35 | I21: =(F21*G21)/H21 -> 64.8
B22: Flint Hills Hardisty (WCS Pricing) | C22: 5.85 | D22: =C22*2 -> 11.7 | E22: =IF(C22>0, 2, 0) -> 2 | F22: =E22+D22 -> 13.7 | G22: =$G$15 -> 210 | H22: 35 | I22: =(F22*G22)/H22 -> 82.2 | W22: WCS Blend Density History | X22: Jan | Y22: Feb | Z22: Mar | AA22: Apr | AB22: May | AC22: June | AD22: July | AE22: Aug | AF22: Sept | AG22: Oct | AH22: Nov | AI22: Dec
W23: 2023 WCS Blended Density | X23: 918 | Y23: 922.1 | Z23: 923.1 | AA23: 921.9 | AB23: 924.7 | AC23: 926.9 | AD23: 931.4 | AE23: 932 | AF23: 935.5 | AG23: 928.3 | AH23: 926.3 | AI23: 923.1
W24: 2024 WCS Blended Density | X24: 922.3 | Y24: 922.1 | Z24: 924.4 | AA24: 921.1 | AB24: 924.8 | AC24: 928.6 | AD24: 933.6 | AE24: 931.2 | AF24: 936.1 | AG24: 930.8 | AH24: 926.2 | AI24: 921.4
B25: Blended Crude Netback Comparison | C25: =Inputs!C4 -> 45413 | W25: 2025 WCS Blended Density | X25: 920.4 | Y25: 919.7 | Z25: 922.3 | AA25: 921.8 | AB25: 923.8 | AC25: 928
B27: Receipt Location - Blended Crude | C27: =B15 -> Nipisi North Truck Terminal (Rainbow P/L) | D27: =B17 -> Nipisi South Truck Terminal (Nipisi P/L) | E27: =B16 -> Utikuma North Truck Terminal (Nipisi P/L) | F27: =B18 -> Utikuma South Truck Terminal (Nipisi P/L) | G27: =B19 -> Mitsue Truck Terminal (Nipisi P/L) | H27: Marten Hills P/L (Rainbow P/L) | I27: =B21 -> Gibsons Edmonton (CHV Pricing) | J27: =B22 -> Flint Hills Hardisty (WCS Pricing) | X27: Blended Crude Density to get to 350cSt (Paper Blend Target)
W28: Customer Producers | X28: 45200 | Y28: 45231 | Z28: 45261 | AA28: 45292 | AB28: 45323 | AC28: 45352 | AD28: 45383 | AE28: 45413 | AF28: 45444 | AG28: 45474 | AH28: 45505 | AI28: 45536
B29: Raw Crude Volume (M3/M) | C29: =Inputs!$C$5 -> 21147 | D29: =Inputs!$C$5 -> 21147 | E29: =Inputs!$C$5 -> 21147 | F29: =Inputs!$C$5 -> 21147 | G29: =Inputs!$C$5 -> 21147 | H29: =Inputs!$C$5 -> 21147 | I29: =Inputs!$C$5 -> 21147 | J29: =Inputs!$C$5 -> 21147 | W29: Spur | X29: 925.6 | Y29: 923 | Z29: 921.8 | AA29: 921.2 | AB29: 921.2 | AC29: 918.1 | AD29: 921.5 | AE29: 924.4 | AF29: 931 | AG29: 934.8 | AH29: 930.9 | AI29: 927.8
B30: Raw Crude Density (KG/M3) | C30: =Inputs!C16 -> 965 | D30: =$C$30 -> 965 | E30: =$C$30 -> 965 | F30: =$C$30 -> 965 | G30: =$C$30 -> 965 | H30: =$C$30 -> 965 | I30: =$C$30 -> 965 | J30: =$C$30 -> 965 | W30: Tamarack | X30: 925.6 | Y30: 923 | Z30: 921.1 | AA30: 921.3 | AB30: 920.9 | AC30: 923 | AD30: 923.1 | AE30: 926.2 | AF30: 930.6 | AG30: 935 | AH30: 931 | AI30: 928
B31: Blended Crude Target Density (KG/M3) | C31: =Inputs!$C$18 -> 924.4 | D31: =Inputs!$C$18 -> 924.4 | E31: =Inputs!$C$18 -> 924.4 | F31: =Inputs!$C$18 -> 924.4 | G31: =Inputs!$C$18 -> 924.4 | H31: =Inputs!$C$18 -> 924.4 | I31: =Inputs!$C$18 -> 924.4 | J31: =Inputs!$C$18 -> 924.4 | W31: Obsidian | X31: 917.9 | Y31: 914.6 | Z31: 912.3 | AA31: 912.9 | AB31: 915.3 | AC31: 915.8 | AD31: 914.8 | AE31: 916.4 | AF31: 919.7 | AG31: 929.2 | AH31: 925.3 | AI31: 921.6
B32: Raw Crude Sulphur (%) | C32: 4 | D32: 4 | E32: 4 | F32: 4 | G32: 4 | H32: =C32 -> 4 | I32: 4 | J32: 4 | W32: Baytex | AB32: 921 | AC32: 921.5 | AD32: 916.1 | AE32: 917.9 | AF32: 920.7 | AG32: 929.8
B33: Raw Crude TAN | C33: =Inputs!$C$6 -> 0.65 | D33: =Inputs!$C$6 -> 0.65 | E33: =Inputs!$C$6 -> 0.65 | F33: =Inputs!$C$6 -> 0.65 | G33: =Inputs!$C$6 -> 0.65 | H33: =Inputs!$C$6 -> 0.65 | I33: =Inputs!$C$6 -> 0.65 | J33: =Inputs!$C$6 -> 0.65 | W33: Headwater | AD33: 913.4 | AE33: 926.5 | AF33: 928.5 | AG33: 932.5
B34: Condensate Density (KG/M3) | C34: =Inputs!C14 -> 737 | D34: =Inputs!C7 -> 660 | E34: =Inputs!$C$7 -> 660 | F34: =Inputs!$C$7 -> 660 | G34: =Inputs!C7 -> 660 | H34: =C34 -> 737 | I34: =Inputs!C13 -> 730 | J34: =Inputs!C13 -> 730
B36: Stream | C36: CHV | D36: CWH | E36: CHV | F36: CHV | G36: CHV | H36: CHV | I36: CHV | J36: WCS
B37: Month | C37: =Inputs!$C$4 -> 45413 | D37: =Inputs!$C$4 -> 45413 | E37: =Inputs!$C$4 -> 45413 | F37: =Inputs!$C$4 -> 45413 | G37: =Inputs!$C$4 -> 45413 | H37: =Inputs!$C$4 -> 45413 | I37: =Inputs!$C$4 -> 45413 | J37: =Inputs!$C$4 -> 45413
B38: WTI (USD/BBL) | C38: =_xlfn.XLOOKUP(C$37, MonthlyData!$B:$B, MonthlyData!$D:$D) -> 78.62 | D38: =$C$38 -> 78.62 | E38: =$C$38 -> 78.62 | F38: =$C$38 -> 78.62 | G38: =$C$38 -> 78.62 | H38: =$C$38 -> 78.62 | I38: =$C$38 -> 78.62 | J38: =$C$38 -> 78.62
B39: WCS Diff (USD/BBL) | C39: 0 | D39: 0 | E39: 0 | F39: 0 | G39: 0 | H39: 0 | I39: 0 | J39: =_xlfn.XLOOKUP(C25, MonthlyData!$B:$B, MonthlyData!$AA:$AA) -> -13.07
B40: CHV Diff (USD/BBL) | C40: =_xlfn.XLOOKUP(C$37, MonthlyData!$B:$B, MonthlyData!$BP:$BP) -> -12.82 | D40: =C40 -> -12.82 | E40: =$C$40 -> -12.82 | F40: =$C$40 -> -12.82 | G40: =D40 -> -12.82 | H40: =C40 -> -12.82 | I40: =C40 -> -12.82 | J40: 0
B41: Premium/Discount (USD/BBL) | C41: 0 | D41: 0.15 | E41: 0 | F41: 0 | G41: 0 | H41: 0 | I41: 0 | J41: 0.4
B42: FX | C42: =_xlfn.XLOOKUP(C$37, MonthlyData!$B:$B, MonthlyData!$E:$E) -> 1.36695 | D42: =$C$42 -> 1.36695 | E42: =$C$42 -> 1.36695 | F42: =$C$42 -> 1.36695 | G42: =$C$42 -> 1.36695 | H42: =$C$42 -> 1.36695 | I42: =$C$42 -> 1.36695 | J42: =$C$42 -> 1.36695
B43: Reference Price | C43: =(C38+C39+C40+C41)*6.2898105*C42 -> 565.73896 | D43: =(D38+D39+D40+D41)*6.2898105*D42 -> 567.02863 | E43: =(E38+E39+E40+E41)*6.2898105*E42 -> 565.73896 | F43: =(F38+F39+F40+F41)*6.2898105*F42 -> 565.73896 | G43: =(G38+G39+G40+G41)*6.2898105*G42 -> 565.73896 | H43: =(H38+H39+H40+H41)*6.2898105*H42 -> 565.73896 | I43: =(I38+I39+I40+I41)*6.2898105*I42 -> 565.73896 | J43: =(J38+J39+J40+J41)*6.2898105*J42 -> 567.02863
B44: Terminal Fee (2025$) | C44: ='NipNorthTT Novacor Rainbow'!B47 -> -5 | D44: =-D106 -> -4.7 | E44: =-Inputs!C19 -> -5.25 | F44: =-Inputs!$C$20 -> -4.7 | G44: =-G106 -> -4.75 | H44: 0 | I44: =-H106 -> 0 | J44: =-I106 -> -5
B45: Raw Crude Trucking Cost | C45: =-(I15*'NipNorthTT Novacor Rainbow'!F8)/'NipNorthTT Novacor Rainbow'!F12 -> -9.7174148 | D45: =-(I17*'UtikuSouthTT DilFee Nipisi'!C101)/'UtikuSouthTT DilFee Nipisi'!C106 -> -14.76637 | E45: =-(I16*'UtikuNorthTT DilFee Nipisi'!C101)/'UtikuNorthTT DilFee Nipisi'!C106 -> -11.602148 | F45: =-(I18*'UtikuSouthTT DilFee Nipisi'!C101)/'UtikuSouthTT DilFee Nipisi'!C106 -> -14.76637 | G45: =-(I19*'KINGMitsueTT Dil Fee Nipisi'!C100)/'KINGMitsueTT Dil Fee Nipisi'!C105 -> -21.094814 | H45: =-(I20*'KingMH-Plains Novacor Rainbow'!B9)/'KingMH-Plains Novacor Rainbow'!F12 -> -27.208762 | I45: =-(I21*'Gibsons Novacor Edm'!B9)/'Gibsons Novacor Edm'!F12 -> -52.86423 | J45: =-(I22*'FlintHills Novacor Hardisty'!B9)/'FlintHills Novacor Hardisty'!F12 -> -67.20519
...

Sheet NipNorthTT Novacor Rainbow
A3: NOVACOR: Condensate Addition & Shrinkage Calculations
F7: RESULTS | J7: Rainbow SW (Interface) | K7: RP2 C5+ | L7: CHV
A8: Date | B8: ='Spur-Netback'!C37 -> 45413 | E8: Volume of Dry Crude = | F8: =B9 -> 21147 | G8: m3 | I8: Density (KG/M3) | J8: 815 | K8: =Inputs!C14 -> 737 | L8: =Inputs!C18 -> 924.4
A9: Volume of Raw Crude = | B9: =Inputs!C5 -> 21147 | C9: M3 | E9: % C5+ in Total Blend (Fc) = | F9: =B36 -> 19.324663 | G9: % | I9: Sulfur (%Swt) | J9: 0.35 | K9: 0.1 | L9: 4
A10: Density of Raw Crude = | B10: =Inputs!C16 -> 965 | C10: KG/M3 | E10: Condensate Required in Blend= | F10: =((F9/100)*B9)/(1-F9/100) -> 5065.4719 | G10: m3 | I10: WTI (USD/BBL) | J10: =_xlfn.XLOOKUP($B$8,MonthlyData!$B:$B,MonthlyData!$D:$D) -> 78.62 | K10: =J10 -> 78.62 | L10: =J10 -> 78.62
A11: Density of Condensate (RP2 C5+) = | B11: =K8 -> 737 | C11: KG/M3 | E11: Shrinkage Volume = | F11: =(B9+F10)*B37/100 -> 98.119075 | G11: m3 | I11: FX (CAD/USD) | J11: =_xlfn.XLOOKUP($B$8,MonthlyData!$B:$B,MonthlyData!$E:$E) -> 1.36695 | K11: =J11 -> 1.36695 | L11: =K11 -> 1.36695
A12: Density of Target Blend = | B12: =L8 -> 924.4 | C12: KG/M3 | E12: Volume of Blend = | F12: =B9+F10-F11 -> 26114.353 | G12: m3 | I12: Diff (USD/BBL) | J12: =_xlfn.XLOOKUP($B$8,MonthlyData!$B:$B,MonthlyData!$F:$F) -> -3.78 | K12: =_xlfn.XLOOKUP($B$8,MonthlyData!$B:$B,MonthlyData!$M:$M) -> -4.19 | L12: =_xlfn.XLOOKUP($B$8,MonthlyData!$B:$B,MonthlyData!$BP:$BP) -> -12.82
I13: WADF (CAD/M3) | J13: =_xlfn.XLOOKUP($B$8,MonthlyData!$B:$B,MonthlyData!$G:$G) -> 0.015 | K13: =_xlfn.XLOOKUP($B$8,MonthlyData!$B:$B,MonthlyData!$X:$X) -> -4.27 | L13: 0
A14: Raw Crude Density - as measured by Producer or at Truck Unload or Oil Analysis. | I14: Ref Price | J14: =J13+(J10+J12)*6.29287*J11 -> 643.79157 | K14: =K13+(K10+K12)*6.29287*K11 -> 635.97974 | L14: =L13+(L10+L12)*6.2898105*L11 -> 565.73896
A15: Condensate Density - as reported by CM or Plains or Producer/Customer deliveries in the delivery month. | E15: Apparent Condensate | F15: =F10-F11 -> 4967.3529 | I15: EQ | J15: =IF(J8>825,(825-J8)*0.49,IF(J8<800,(J8-800)*0.49,0))+(0.5-J9)*13.8 -> 2.07 | K15: =(750-K8)*$B$18+(0.2-$K$9)*13.8 -> 3.59 | L15: 0
A16: Target Blend Density - CHV density, as reported by CM or Plains or Producer/Customer, in the delivery month | E16: Shrinkage as: %C5+ | F16: =F11/F10*100 -> 1.9370174 | I16: Tariff on Purchase
E17: Shrinkage as: %Blend | F17: =(F19-F12)/F19*100 -> 0.3743221 | I17: Trucking on Purchase
A18: C5 Density Slope | B18: =_xlfn.XLOOKUP($B$8,MonthlyData!$B:$B,MonthlyData!$Y:$Y) -> 0.17 | E18: Shrinkage as: % Shrunk Blend | F18: =(F19-F12)/F12*100 -> 0.37572853 | I18: Other
A19: Rainbow Interface % | B19: 0.0197 | E19: vol blend w/o shrinkage | F19: =F8+F10 -> 26212.472 | I19: Netback | J19: =SUM(J14:J18) -> 645.86157 | K19: =SUM(K14:K18) -> 639.56974 | L19: =SUM(L14:L18) -> 565.73896
E20: C5+ as % of dry crude | F20: =F10/F8*100 -> 23.95362
E21: C5+ as % of blend | F21: =F10/F12*100 -> 19.397272
A24: NovaCor Eqn
A25: ITERATIONS: | D25: vol C5+ | E25: Density Blend
A26: % C5+ in Total Blend (Fc) = | B26: =((B10-B12)/(B10-B11))*100 -> 17.807018 | C26: % | D26: =(B26/100*$B$9)/(1-B26/100) -> 4581.4739 | E26: =(D26*$B$11+$B$9*$B$10)/(D26+$B$9)/(1-B27/100) -> 927.68764
A27: Blend Shrinkage Factor (Sf) = | B27: =(0.0266*B26)-(0.0004*(POWER(B26,2)))+(0.000001339*(POWER(B26,3))) -> 0.35439128 | C27: % | D27: =(B9/(1-B26/100))*(B26/100) -> 4581.4739
A28: % C5+ in Total Blend (Fc) = | B28: =(((($B$10-$B$12)/($B$10-$B$11))+((B27/100)*$B$12)/($B$10-$B$11)))*100 -> 19.243857 | C28: % | D28: =(B28/100*$B$9)/(1-B28/100) -> 5039.2431 | E28: =(D28*$B$11+$B$9*$B$10)/(D28+$B$9)/(1-B29/100) -> 924.57543
A29: Blend Shrinkage Factor (Sf) = | B29: =(0.0266*B28)-(0.0004*(POWER(B28,2)))+(0.000001339*(POWER(B28,3))) -> 0.37329856 | C29: %
A30: % C5+ in Total Blend (Fc) = | B30: =(((($B$10-$B$12)/($B$10-$B$11))+((B29/100)*$B$12)/($B$10-$B$11)))*100 -> 19.320514 | C30: % | D30: =(B30/100*$B$9)/(1-B30/100) -> 5064.1239 | E30: =(D30*$B$11+$B$9*$B$10)/(D30+$B$9)/(1-B31/100) -> 924.40901
A31: Blend Shrinkage Factor (Sf) = | B31: =(0.0266*B30)-(0.0004*(POWER(B30,2)))+(0.000001339*(POWER(B30,3))) -> 0.37426964 | C31: %
A32: % C5+ in Total Blend (Fc) = | B32: =(((($B$10-$B$12)/($B$10-$B$11))+((B31/100)*$B$12)/($B$10-$B$11)))*100 -> 19.324451 | C32: % | D32: =(B32/100*$B$9)/(1-B32/100) -> 5065.403 | E32: =(D32*$B$11+$B$9*$B$10)/(D32+$B$9)/(1-B33/100) -> 924.40046
A33: Blend Shrinkage Factor (Sf) = | B33: =(0.0266*B32)-(0.0004*(POWER(B32,2)))+(0.000001339*(POWER(B32,3))) -> 0.37431942 | C33: %
A34: % C5+ in Total Blend (Fc) = | B34: =(((($B$10-$B$12)/($B$10-$B$11))+((B33/100)*$B$12)/($B$10-$B$11)))*100 -> 19.324653 | C34: % | D34: =(B34/100*$B$9)/(1-B34/100) -> 5065.4686 | E34: =(D34*$B$11+$B$9*$B$10)/(D34+$B$9)/(1-B35/100) -> 924.40002
A35: Blend Shrinkage Factor (Sf) = | B35: =(0.0266*B34)-(0.0004*(POWER(B34,2)))+(0.000001339*(POWER(B34,3))) -> 0.37432197 | C35: %
A36: % C5+ in Total Blend (Fc) = | B36: =(((($B$10-$B$12)/($B$10-$B$11))+((B35/100)*$B$12)/($B$10-$B$11)))*100 -> 19.324663 | C36: % | D36: =(B36/100*$B$9)/(1-B36/100) -> 5065.4719 | E36: =(D36*$B$11+$B$9*$B$10)/(D36+$B$9)/(1-B37/100) -> 924.4
A37: Blend Shrinkage Factor (Sf) = | B37: =(0.0266*B36)-(0.0004*(POWER(B36,2)))+(0.000001339*(POWER(B36,3))) -> 0.3743221 | C37: %
A39: Pricing | E39: =1/1.3378 -> 0.74749589
A41: Condensate price @ Edmonton | B41: =$K$19 -> 639.56974 | C41: CAD/M3
A42: C5 RP2 Edm-Nipisi Toll: | B42: 17.5 | C42: CAD/M3
A43: C5 ENB/PMC Terminalling | B43: 3.47 | C43: CAD/M3
A44: Total Condensate price: | B44: =SUM(B41:B43) -> 660.53974 | C44: CAD/M3
A46: CHV Price (Edmonton) | B46: =$L$19 -> 565.73896 | C46: CAD/M3
A47: Rainbow Pipeline Terminal Fee | B47: -5 | C47: CAD/M3
A48: Rainbow Pipeline Tariff | B48: -17.5 | C48: CAD/M3
A49: Rainbow Inferface Fee | B49: =($L$19-$J$19)*$B$19 -> -1.5784156 | C49: CAD/M3
A50: Heavy Blend in Rainbow Nipisi Storage | B50: =SUM(B46:B49) -> 541.66054 | C50: CAD/M3
...

Sheet UtikuNorthTT DilFee Nipisi
A1: Diluent Optimization Benefit - ESTIMATED (NO CRUDE VISCOSITY DATA)
A4: PRICING ASSUMPTIONS: | C4: WADF | D4: PAR | E4: STREAM
A5: MONTH: | B5: ='Spur-Netback'!C37 -> 45413 | C5: $Cdn/m3 | D5: $Cdn/m3 | E5: $Cdn/m3 | G5: =B5 -> 45413 | H5: CONDENSATE EQ: | I5: $/m3 | J5: C4 Content | K5: Penalty $/m3 | L5: Penalty $/m3 /.1%
A6: WTI: | B6: =_xlfn.XLOOKUP($B$5,MonthlyData!$B:$B,MonthlyData!$D:$D) -> 78.62 | H6: C5+ Allow Price | I6: =_xlfn.XLOOKUP($B$5,MonthlyData!$B:$B,MonthlyData!$Z:$Z) -> 636.91 | J6: <=5.0% | K6: 0 | L6: 0
A7: FX: | B7: =_xlfn.XLOOKUP($B$5,MonthlyData!$B:$B,MonthlyData!$E:$E) -> 1.36695 | H7: Butane Price | I7: 0 | J7: >5.0%-7.0% | K7: =ROUND(I6-I8,2) -> 636.91 | L7: =ROUND(K7/1000,6) -> 0.63691
A8: CHV INDEX ($US/bbl): | B8: =_xlfn.XLOOKUP($B$5,MonthlyData!$B:$B,MonthlyData!$BP:$BP) -> -12.82 | E8: =(B6+B8)*6.2898105*B7 -> 565.73896 | H8: 50% of Butane Value | I8: =ROUND(I7/2,2) -> 0 | J8: > 7.0% | K8: =ROUND(I6,2) -> 636.91 | L8: =ROUND(K8/1000,6) -> 0.63691
A9: C5+ INDEX ($US/bbl): | B9: =_xlfn.XLOOKUP($B$5,MonthlyData!$B:$B,MonthlyData!$M:$M) -> -4.19 | C9: =_xlfn.XLOOKUP($B$5,MonthlyData!$B:$B,MonthlyData!$X:$X) -> -4.27 | D9: =(($B$6+B9)*6.29287*$B$7)+C9 -> 635.97974 | E9: =D9-C9 -> 640.24974 | H9: Density Slope (C5+) | I9: =_xlfn.XLOOKUP($B$5,MonthlyData!$B:$B,MonthlyData!$Y:$Y) -> 0.17 | J9: $ / m3 per kg / m3 | L9: 750 kg/m3
A10: C4 Price %WTI (Landed): | B10: =_xlfn.XLOOKUP($B$5,MonthlyData!$B:$B,MonthlyData!$AM:$AM)*Inputs!C28 -> 0.5225 | E10: =(B6*B10)*6.29287*B7+D10 -> 353.36272 | H10: Sulphur | I10: =I13 -> 1.38 | J10: $ / m3 per .1 wt% | L10: .2% wt
A11: \ | B11: =B10 -> 0.5225 | H11: CRUDE (INDUSTRY) EQ:
A12: C4 Diff: | B12: =1-B11 -> 0.4775 | C12: (1 - 62.4%) | H12: Density Slope (Crude) | I12: 0.49 | J12: $ / m3 per kg / m3 | K12: Heavy Allow Price: | L12: =_xlfn.XLOOKUP($B$5,MonthlyData!$B:$B,MonthlyData!$AE:$AE) -> 0
A13: C4 Purchase Price ($US/bbl): | B13: =B6*B11 -> 41.07895 | H13: Sulphur | I13: 1.38 | J13: $ / m3 per .1 wt% | K13: Enb. Ref Temp: | L13: =_xlfn.XLOOKUP($B$5,MonthlyData!$B:$B,MonthlyData!$AF:$AF) -> 0
A14: C4 Diff to WTI ($US/bbl): | B14: =B13-B6 -> -37.54105 | D14: C4 vs. C5+: | E14: =E10-I15 -> -304.94495 | H14: Calculated EQ CREDIT: | I14: =(750-$L$14)*$I$9+(0.2-$L$15)*$I$10*10 -> 18.05793 | K14: C5+ Density: | L14: =Inputs!C7 -> 660
H15: C5+ Price after EQ: | I15: =E9+I14 -> 658.30767 | K15: C5+ Sulfur: | L15: =Inputs!C8 -> 0.00015
A18: Condensate Only - Paper Blend | N18: SCENARIO #1 - IF C5+ ONLY:
A19: API 12.3 Sec.5.3
B20: TEMP CORR. VOLUMES & DENSITY INPUTS | H20: RESULTS | O20: Value | R20: Result
B21: m3 | C21: Dens @ 15C | D21: % of Blend | H21: Shrinkage Percent | I21: SHRINKAGE | J21: Sum of Volumes | K21: Resultant Volume | N21: Raw Heavy Volume | O21: =B22 -> 21147 | Q21: Raw (m3) | R21: =O32 -> 21147
A22: RAW CRUDE OIL: | B22: =Inputs!C5 -> 21147 | C22: =Inputs!C16 -> 965 | D22: =B22/B26 -> 0.86688525 | H22: % | I22: m3 | N22: Raw Heavy Density | O22: =C22 -> 965 | Q22: C5 (m3) | R22: =SUM(O34:S34) -> 3666.2356
A23: Butane: | B23: 0 | C23: 575 | D23: =B23/B26 -> 0 | H23: =IFERROR(26900*F36*(100-F36)^0.819*(I36-J36)^2.28,0) -> 0 | I23: =IFERROR(H23/100*(B36+D36),0) -> 0 | J23: =B36+D36 -> 21147 | K23: =B36+D36-I23 -> 21147 | N23: C5 Density | O23: =C24 -> 660 | Q23: Delivered (m3) | R23: =S40 -> 24693.378
A24: Condensate: | B24: =(C22-B28)/(B28-C24)*B22 -> 3247.2322 | C24: =L14 -> 660 | D24: =B24/B26 -> 0.13311475 | H24: =IFERROR(26900*F37*(100-F37)^0.819*(I37-J37)^2.28,0) -> 0.3733277 | I24: =IFERROR(H24/100*(B37+D37),0) -> 91.070427 | J24: =B37+D37 -> 24394.232 | K24: =B37+D37-I24 -> 24303.162 | N24: Target Density | O24: =B28 -> 924.4 | Q24: Shrinkage (m3) | R24: =R23-SUM(R21:R22) -> -119.8572
H25: =IFERROR(26900*F38*(100-F38)^0.819*(I38-J38)^2.28,0) -> 0 | I25: =IFERROR(H25/100*(B38+D38),0) -> 0 | J25: =B38+D38 -> 24303.162 | K25: =B38+D38-I25 -> 24303.162
A26: Total Receipts: | B26: =SUM(B22:B25) -> 24394.232 | D26: =SUM(D22:D25) -> 1 | H26: =IF(I26=0,"",(I26/K26)) -> 0.0037472666 | I26: =(SUM(I23:I25))*1 -> 91.070427 | K26: =K25 -> 24303.162 | N26: API 12.3 Heavy Oil Adjusted
A27: Wt.Avg. Kg/m3: | B27: =SUMPRODUCT(B22:B25,C22:C25)/SUM(B22:B25) -> 924.4 | J27: Total Receipts: | K27: =B26 -> 24394.232 | O27: Iteration 1 | P27: Iteration 2 | Q27: Iteration 3 | R27: Iteration 4 | S27: Iteration 5
A28: Target Density | B28: =Inputs!C18 -> 924.4 | J28: Total Shrinkage: | K28: =I26*-1 -> -91.070427 | N28: Target Density | O28: =$B$28 -> 924.4 | P28: =O28 -> 924.4 | Q28: =P28 -> 924.4 | R28: =Q28 -> 924.4 | S28: =R28 -> 924.4
B29: =D49 -> 924.4 | J29: Net Volume: | K29: =K27+K28 -> 24303.162 | N29: Diluent Density | O29: =$C$24 -> 660 | P29: =O29 -> 660 | Q29: =P29 -> 660 | R29: =Q29 -> 660 | S29: =R29 -> 660
J30: Total Shrinkage as % of Total Receipts: | K30: =I26/B26 -> 0.003733277 | N30: Raw Crude Density | O30: =$C$22 -> 965 | P30: =O41 -> 928.48481 | Q30: =P41 -> 924.82147 | R30: =Q41 -> 924.44359 | S30: =R41 -> 924.40451
A31: API 12.3 Sec.5.3
A32: --- Linked to INPUT values above --- | N32: Raw Heavy Volume (m3) | O32: =$B$22 -> 21147 | P32: =O40 -> 24286.911 | Q32: =P40 -> 24650.889 | R32: =Q40 -> 24689.02 | S32: =R40 -> 24692.97
B33: LIGHT | D33: RAW CRUDE OIL | N33: Raw Heavy Mass (kg) | O33: =O32*O30 -> 20406855 | P33: =P32*P30 -> 22550028 | Q33: =Q32*Q30 -> 22797672 | R33: =R32*R30 -> 22823606 | S33: =S32*S30 -> 22826293
B34: Diluent Volume | C34: Average Density | D34: Volume | E34: Average Density | F34: X = DILUENT Volume/(Crude Volume + DILUENT Volume) | G34: XX = CRUDE Volume/(CRUDE Volume + Diluent Volume) | H34: CRUDE + DILUENT BLEND | I34: 1/dL | J34: 1/dH | N34: Diluent Required (m3) | O34: =(O28*O32-O30*O32)/(O29-O28) -> 3247.2322 | P34: =(P28*P32-P30*P32)/(P29-P28) -> 375.21729 | Q34: =(Q28*Q32-Q30*Q32)/(Q29-Q28) -> 39.295037 | R34: =(R28*R32-R30*R32)/(R29-R28) -> 4.0699587 | S34: =(S28*S32-S30*S32)/(S29-S28) -> 0.42105704
B35: m3 | C35: kg/m3 | D35: m3 | E35: kg/m3 | F35: % | G35: % | H35: % | N35: Diluent Mass (kg) | O35: =O34*O29 -> 2143173.3 | P35: =P34*P29 -> 247643.41 | Q35: =Q34*Q29 -> 25934.725 | R35: =R34*R29 -> 2686.1728 | S35: =S34*S29 -> 277.89765
A36: Butane: | B36: =B23 -> 0 | C36: =C23 -> 575 | D36: =B22 -> 21147 | E36: =C22 -> 965 | F36: =IFERROR(B36/(B36+D36)*100,"") -> 0 | G36: =IFERROR(D36/(B36+D36)*100,"") -> 100 | H36: =F36+G36 -> 100 | I36: =IFERROR(1/C36,"") -> 0.0017391304 | J36: =IFERROR(1/E36,"") -> 0.0010362694
A37: Condensate: | B37: =B24 -> 3247.2322 | C37: =C24 -> 660 | D37: =K23 -> 21147 | E37: =E36 -> 965 | F37: =IFERROR(B37/(B37+D37)*100,"") -> 13.311475 | G37: =IFERROR(D37/(B37+D37)*100,"") -> 86.688525 | H37: =F37+G37 -> 100 | I37: =IFERROR(1/C37,"") -> 0.0015151515 | J37: =IFERROR(1/E37,"") -> 0.0010362694 | N37: Diluent as % of Blend | O37: =O34/(O32+O34) -> 0.13311475 | P37: =P34/(P32+P34) -> 0.015214311 | Q37: =Q34/(Q32+Q34) -> 0.0015915247 | R37: =R34/(R32+R34) -> 0.00016482177 | S37: =S34/(S32+S34) -> 1.7051406e-05
A38: OIL: | B38: =K24 -> 24303.162 | C38: =E37 -> 965 | D38: =B25 -> 0 | E38: =C25 -> 0 | F38: =IFERROR(B38/(B38+D38)*100,"") -> 100 | G38: =IFERROR(D38/(B38+D38)*100,"") -> 0 | H38: =F38+G38 -> 100 | I38: =IFERROR(1/C38,"") -> 0.0010362694 | J38: =IFERROR(1/E38,"") | N38: Shrinkage as % of Blend | O38: =31700*O37*(100-O37*100)^0.819*(1/O29-1/O30)^2.28 -> 0.004399438 | P38: =31700*P37*(100-P37*100)^0.819*(1/P29-1/P30)^2.28 -> 0.0004557311 | Q38: =31700*Q37*(100-Q37*100)^0.819*(1/Q29-1/Q30)^2.28 -> 4.7148425e-05 | R38: =31700*R37*(100-R37*100)^0.819*(1/R29-1/R30)^2.28 -> 4.87716e-06 | S38: =31700*S37*(100-S37*100)^0.819*(1/S29-1/S30)^2.28 -> 5.0449949e-07
A39: dL | B39: = Density of Light | N39: Shrinkage (m3) | O39: =-O38*(O32+O34) -> -107.32091 | P39: =-P38*(P32+P34) -> -11.239299 | Q39: =-Q38*(Q32+Q34) -> -1.1641033 | R39: =-R38*(R32+R34) -> -0.12043215 | S39: =-S38*(S32+S34) -> -0.012457803
A40: dH | B40: = Density of Heavy | N40: Volume After Shrinkage | O40: =O32+O34+O39 -> 24286.911 | P40: =P32+P34+P39 -> 24650.889 | Q40: =Q32+Q34+Q39 -> 24689.02 | R40: =R32+R34+R39 -> 24692.97 | S40: =S32+S34+S39 -> 24693.378
A41: X | B41: = % concentraion of Diluent. (i.e., Diluent percentage of total blend). | N41: Density After Shrinkage | O41: =(O33+O35)/O40 -> 928.48481 | P41: =(P33+P35)/P40 -> 924.82147 | Q41: =(Q33+Q35)/Q40 -> 924.44359 | R41: =(R33+R35)/R40 -> 924.40451 | S41: =(S33+S35)/S40 -> 924.40047
A42: XX | B42: = % concentraion of Crude. (i.e., Crude percentage of total blend).
A44: Condensate Only - Net Sales Calculation | N44: SCENARIO #1 - FINANCIAL RESULTS:
C45: m3 | D45: kg/m3 | E45: % Inject | F45: % of Blend | P45: m3 | Q45: kg/m3 | R45: % Inject | S45: % of Blend
...

Sheet UtikuSouthTT DilFee Nipisi
A1: Diluent Optimization Benefit - ESTIMATED (NO CRUDE VISCOSITY DATA)
A4: PRICING ASSUMPTIONS: | C4: WADF | D4: PAR | E4: STREAM
A5: MONTH: | B5: ='Spur-Netback'!C37 -> 45413 | C5: $Cdn/m3 | D5: $Cdn/m3 | E5: $Cdn/m3 | G5: =B5 -> 45413 | H5: CONDENSATE EQ: | I5: $/m3 | J5: C4 Content | K5: Penalty $/m3 | L5: Penalty $/m3 /.1%
A6: WTI: | B6: =_xlfn.XLOOKUP($B$5,MonthlyData!$B:$B,MonthlyData!$D:$D) -> 78.62 | H6: C5+ Allow Price | I6: =_xlfn.XLOOKUP($B$5,MonthlyData!$B:$B,MonthlyData!$Z:$Z) -> 636.91 | J6: <=5.0% | K6: 0 | L6: 0
A7: FX: | B7: =_xlfn.XLOOKUP($B$5,MonthlyData!$B:$B,MonthlyData!$E:$E) -> 1.36695 | H7: Butane Price | I7: 0 | J7: >5.0%-7.0% | K7: =ROUND(I6-I8,2) -> 636.91 | L7: =ROUND(K7/1000,6) -> 0.63691
A8: CHV INDEX ($US/bbl): | B8: =_xlfn.XLOOKUP($B$5,MonthlyData!$B:$B,MonthlyData!$BP:$BP) -> -12.82 | E8: =(B6+B8)*6.2898105*B7 -> 565.73896 | H8: 50% of Butane Value | I8: =ROUND(I7/2,2) -> 0 | J8: > 7.0% | K8: =ROUND(I6,2) -> 636.91 | L8: =ROUND(K8/1000,6) -> 0.63691
A9: C5+ INDEX ($US/bbl): | B9: =_xlfn.XLOOKUP($B$5,MonthlyData!$B:$B,MonthlyData!$M:$M) -> -4.19 | C9: =_xlfn.XLOOKUP($B$5,MonthlyData!$B:$B,MonthlyData!$X:$X) -> -4.27 | D9: =(($B$6+B9)*6.29287*$B$7)+C9 -> 635.97974 | E9: =D9-C9 -> 640.24974 | H9: Density Slope (C5+) | I9: =_xlfn.XLOOKUP($B$5,MonthlyData!$B:$B,MonthlyData!$Y:$Y) -> 0.17 | J9: $ / m3 per kg / m3 | L9: 750 kg/m3
A10: C4 Price %WTI (Landed): | B10: =_xlfn.XLOOKUP($B$5,MonthlyData!$B:$B,MonthlyData!$AM:$AM) -> 0.475 | E10: =(B6*B10)*6.29287*B7+D10 -> 321.23883 | H10: Sulphur | I10: =I13 -> 1.38 | J10: $ / m3 per .1 wt% | L10: .2% wt
A11: \ | B11: =B10 -> 0.475 | H11: CRUDE (INDUSTRY) EQ:
A12: C4 Diff: | B12: =1-B11 -> 0.525 | C12: (1 - 62.4%) | H12: Density Slope (Crude) | I12: 0.49 | J12: $ / m3 per kg / m3 | K12: Heavy Allow Price: | L12: =_xlfn.XLOOKUP($B$5,MonthlyData!$B:$B,MonthlyData!$AE:$AE) -> 0
A13: C4 Purchase Price ($US/bbl): | B13: =B6*B11 -> 37.3445 | H13: Sulphur | I13: 1.38 | J13: $ / m3 per .1 wt% | K13: Enb. Ref Temp: | L13: =_xlfn.XLOOKUP($B$5,MonthlyData!$B:$B,MonthlyData!$AF:$AF) -> 0
A14: C4 Diff to WTI ($US/bbl): | B14: =B13-B6 -> -41.2755 | D14: C4 vs. C5+: | E14: =E10-I15 -> -337.06883 | H14: Calculated EQ CREDIT: | I14: =(750-$L$14)*$I$9+(0.2-$L$15)*$I$10*10 -> 18.05793 | K14: C5+ Density: | L14: =Inputs!C7 -> 660
H15: C5+ Price after EQ: | I15: =E9+I14 -> 658.30767 | K15: C5+ Sulfur: | L15: =Inputs!C8 -> 0.00015
A18: Condensate Only - Paper Blend | N18: SCENARIO #1 - IF C5+ ONLY:
A19: API 12.3 Sec.5.3
B20: TEMP CORR. VOLUMES & DENSITY INPUTS | H20: RESULTS | O20: Value | R20: Result
B21: m3 | C21: Dens @ 15C | D21: % of Blend | H21: Shrinkage Percent | I21: SHRINKAGE | J21: Sum of Volumes | K21: Resultant Volume | N21: Raw Heavy Volume | O21: =B22 -> 21147 | Q21: Raw (m3) | R21: =O32 -> 21147
A22: RAW CRUDE OIL: | B22: =Inputs!C5 -> 21147 | C22: =Inputs!C16 -> 965 | D22: =B22/B26 -> 0.86688525 | H22: % | I22: m3 | N22: Raw Heavy Density | O22: =C22 -> 965 | Q22: C5 (m3) | R22: =SUM(O34:S34) -> 3666.2356
A23: Butane: | B23: 0 | C23: 575 | D23: =B23/B26 -> 0 | H23: =IFERROR(26900*F36*(100-F36)^0.819*(I36-J36)^2.28,0) -> 0 | I23: =IFERROR(H23/100*(B36+D36),0) -> 0 | J23: =B36+D36 -> 21147 | K23: =B36+D36-I23 -> 21147 | N23: C5 Density | O23: =C24 -> 660 | Q23: Delivered (m3) | R23: =S40 -> 24693.378
A24: Condensate: | B24: =(C22-B28)/(B28-C24)*B22 -> 3247.2322 | C24: =L14 -> 660 | D24: =B24/B26 -> 0.13311475 | H24: =IFERROR(26900*F37*(100-F37)^0.819*(I37-J37)^2.28,0) -> 0.3733277 | I24: =IFERROR(H24/100*(B37+D37),0) -> 91.070427 | J24: =B37+D37 -> 24394.232 | K24: =B37+D37-I24 -> 24303.162 | N24: Target Density | O24: =B28 -> 924.4 | Q24: Shrinkage (m3) | R24: =R23-SUM(R21:R22) -> -119.8572
H25: =IFERROR(26900*F38*(100-F38)^0.819*(I38-J38)^2.28,0) -> 0 | I25: =IFERROR(H25/100*(B38+D38),0) -> 0 | J25: =B38+D38 -> 24303.162 | K25: =B38+D38-I25 -> 24303.162
A26: Total Receipts: | B26: =SUM(B22:B25) -> 24394.232 | D26: =SUM(D22:D25) -> 1 | H26: =IF(I26=0,"",(I26/K26)) -> 0.0037472666 | I26: =(SUM(I23:I25))*1 -> 91.070427 | K26: =K25 -> 24303.162 | N26: API 12.3 Heavy Oil Adjusted
A27: Wt.Avg. Kg/m3: | B27: =SUMPRODUCT(B22:B25,C22:C25)/SUM(B22:B25) -> 924.4 | J27: Total Receipts: | K27: =B26 -> 24394.232 | O27: Iteration 1 | P27: Iteration 2 | Q27: Iteration 3 | R27: Iteration 4 | S27: Iteration 5
A28: Target Density | B28: =Inputs!C18 -> 924.4 | J28: Total Shrinkage: | K28: =I26*-1 -> -91.070427 | N28: Target Density | O28: =$B$28 -> 924.4 | P28: =O28 -> 924.4 | Q28: =P28 -> 924.4 | R28: =Q28 -> 924.4 | S28: =R28 -> 924.4
B29: =D49 -> 924.4 | J29: Net Volume: | K29: =K27+K28 -> 24303.162 | N29: Diluent Density | O29: =$C$24 -> 660 | P29: =O29 -> 660 | Q29: =P29 -> 660 | R29: =Q29 -> 660 | S29: =R29 -> 660
J30: Total Shrinkage as % of Total Receipts: | K30: =I26/B26 -> 0.003733277 | N30: Raw Crude Density | O30: =$C$22 -> 965 | P30: =O41 -> 928.48481 | Q30: =P41 -> 924.82147 | R30: =Q41 -> 924.44359 | S30: =R41 -> 924.40451
A31: API 12.3 Sec.5.3
A32: --- Linked to INPUT values above --- | N32: Raw Heavy Volume (m3) | O32: =$B$22 -> 21147 | P32: =O40 -> 24286.911 | Q32: =P40 -> 24650.889 | R32: =Q40 -> 24689.02 | S32: =R40 -> 24692.97
B33: LIGHT | D33: RAW CRUDE OIL | N33: Raw Heavy Mass (kg) | O33: =O32*O30 -> 20406855 | P33: =P32*P30 -> 22550028 | Q33: =Q32*Q30 -> 22797672 | R33: =R32*R30 -> 22823606 | S33: =S32*S30 -> 22826293
B34: Diluent Volume | C34: Average Density | D34: Volume | E34: Average Density | F34: X = DILUENT Volume/(Crude Volume + DILUENT Volume) | G34: XX = CRUDE Volume/(CRUDE Volume + Diluent Volume) | H34: CRUDE + DILUENT BLEND | I34: 1/dL | J34: 1/dH | N34: Diluent Required (m3) | O34: =(O28*O32-O30*O32)/(O29-O28) -> 3247.2322 | P34: =(P28*P32-P30*P32)/(P29-P28) -> 375.21729 | Q34: =(Q28*Q32-Q30*Q32)/(Q29-Q28) -> 39.295037 | R34: =(R28*R32-R30*R32)/(R29-R28) -> 4.0699587 | S34: =(S28*S32-S30*S32)/(S29-S28) -> 0.42105704
B35: m3 | C35: kg/m3 | D35: m3 | E35: kg/m3 | F35: % | G35: % | H35: % | N35: Diluent Mass (kg) | O35: =O34*O29 -> 2143173.3 | P35: =P34*P29 -> 247643.41 | Q35: =Q34*Q29 -> 25934.725 | R35: =R34*R29 -> 2686.1728 | S35: =S34*S29 -> 277.89765
A36: Butane: | B36: =B23 -> 0 | C36: =C23 -> 575 | D36: =B22 -> 21147 | E36: =C22 -> 965 | F36: =IFERROR(B36/(B36+D36)*100,"") -> 0 | G36: =IFERROR(D36/(B36+D36)*100,"") -> 100 | H36: =F36+G36 -> 100 | I36: =IFERROR(1/C36,"") -> 0.0017391304 | J36: =IFERROR(1/E36,"") -> 0.0010362694
A37: Condensate: | B37: =B24 -> 3247.2322 | C37: =C24 -> 660 | D37: =K23 -> 21147 | E37: =E36 -> 965 | F37: =IFERROR(B37/(B37+D37)*100,"") -> 13.311475 | G37: =IFERROR(D37/(B37+D37)*100,"") -> 86.688525 | H37: =F37+G37 -> 100 | I37: =IFERROR(1/C37,"") -> 0.0015151515 | J37: =IFERROR(1/E37,"") -> 0.0010362694 | N37: Diluent as % of Blend | O37: =O34/(O32+O34) -> 0.13311475 | P37: =P34/(P32+P34) -> 0.015214311 | Q37: =Q34/(Q32+Q34) -> 0.0015915247 | R37: =R34/(R32+R34) -> 0.00016482177 | S37: =S34/(S32+S34) -> 1.7051406e-05
A38: OIL: | B38: =K24 -> 24303.162 | C38: =E37 -> 965 | D38: =B25 -> 0 | E38: =C25 -> 0 | F38: =IFERROR(B38/(B38+D38)*100,"") -> 100 | G38: =IFERROR(D38/(B38+D38)*100,"") -> 0 | H38: =F38+G38 -> 100 | I38: =IFERROR(1/C38,"") -> 0.0010362694 | J38: =IFERROR(1/E38,"") | N38: Shrinkage as % of Blend | O38: =31700*O37*(100-O37*100)^0.819*(1/O29-1/O30)^2.28 -> 0.004399438 | P38: =31700*P37*(100-P37*100)^0.819*(1/P29-1/P30)^2.28 -> 0.0004557311 | Q38: =31700*Q37*(100-Q37*100)^0.819*(1/Q29-1/Q30)^2.28 -> 4.7148425e-05 | R38: =31700*R37*(100-R37*100)^0.819*(1/R29-1/R30)^2.28 -> 4.87716e-06 | S38: =31700*S37*(100-S37*100)^0.819*(1/S29-1/S30)^2.28 -> 5.0449949e-07
A39: dL | B39: = Density of Light | N39: Shrinkage (m3) | O39: =-O38*(O32+O34) -> -107.32091 | P39: =-P38*(P32+P34) -> -11.239299 | Q39: =-Q38*(Q32+Q34) -> -1.1641033 | R39: =-R38*(R32+R34) -> -0.12043215 | S39: =-S38*(S32+S34) -> -0.012457803
A40: dH | B40: = Density of Heavy | N40: Volume After Shrinkage | O40: =O32+O34+O39 -> 24286.911 | P40: =P32+P34+P39 -> 24650.889 | Q40: =Q32+Q34+Q39 -> 24689.02 | R40: =R32+R34+R39 -> 24692.97 | S40: =S32+S34+S39 -> 24693.378
A41: X | B41: = % concentraion of Diluent. (i.e., Diluent percentage of total blend). | N41: Density After Shrinkage | O41: =(O33+O35)/O40 -> 928.48481 | P41: =(P33+P35)/P40 -> 924.82147 | Q41: =(Q33+Q35)/Q40 -> 924.44359 | R41: =(R33+R35)/R40 -> 924.40451 | S41: =(S33+S35)/S40 -> 924.40047
A42: XX | B42: = % concentraion of Crude. (i.e., Crude percentage of total blend).
A44: Condensate Only - Net Sales Calculation | N44: SCENARIO #1 - FINANCIAL RESULTS:
C45: m3 | D45: kg/m3 | E45: % Inject | F45: % of Blend | P45: m3 | Q45: kg/m3 | R45: % Inject | S45: % of Blend
...

Sheet KingMH-Plains Novacor Rainbow
A3: NOVACOR: Condensate Addition & Shrinkage Calculations
F7: RESULTS | J7: Rainbow SW (Interface) | K7: RP2 C5+ | L7: CHV
A8: Date | B8: ='Spur-Netback'!C37 -> 45413 | E8: Volume of Dry Crude = | F8: =B9 -> 21147 | G8: m3 | I8: Density (KG/M3) | J8: 815 | K8: =Inputs!C14 -> 737 | L8: =Inputs!C18 -> 924.4
A9: Volume of Raw Crude = | B9: =Inputs!C5 -> 21147 | C9: M3 | E9: % C5+ in Total Blend (Fc) = | F9: =B36 -> 19.324663 | G9: % | I9: Sulfur (%Swt) | J9: 0.35 | K9: 0.1 | L9: 4
A10: Density of Raw Crude = | B10: =Inputs!C16 -> 965 | C10: KG/M3 | E10: Condensate Required in Blend= | F10: =((F9/100)*B9)/(1-F9/100) -> 5065.4719 | G10: m3 | I10: WTI (USD/BBL) | J10: =_xlfn.XLOOKUP($B$8,MonthlyData!$B:$B,MonthlyData!$D:$D) -> 78.62 | K10: =J10 -> 78.62 | L10: =J10 -> 78.62
A11: Density of Condensate (RP2 C5+) = | B11: =K8 -> 737 | C11: KG/M3 | E11: Shrinkage Volume = | F11: =(B9+F10)*B37/100 -> 98.119075 | G11: m3 | I11: FX (CAD/USD) | J11: =_xlfn.XLOOKUP($B$8,MonthlyData!$B:$B,MonthlyData!$E:$E) -> 1.36695 | K11: =J11 -> 1.36695 | L11: =K11 -> 1.36695
A12: Density of Target Blend = | B12: =L8 -> 924.4 | C12: KG/M3 | E12: Volume of Blend = | F12: =B9+F10-F11 -> 26114.353 | G12: m3 | I12: Diff (USD/BBL) | J12: =_xlfn.XLOOKUP($B$8,MonthlyData!$B:$B,MonthlyData!$F:$F) -> -3.78 | K12: =_xlfn.XLOOKUP($B$8,MonthlyData!$B:$B,MonthlyData!$M:$M) -> -4.19 | L12: =_xlfn.XLOOKUP($B$8,MonthlyData!$B:$B,MonthlyData!$BP:$BP) -> -12.82
I13: WADF (CAD/M3) | J13: =_xlfn.XLOOKUP($B$8,MonthlyData!$B:$B,MonthlyData!$G:$G) -> 0.015 | K13: =_xlfn.XLOOKUP($B$8,MonthlyData!$B:$B,MonthlyData!$X:$X) -> -4.27 | L13: 0
A14: Raw Crude Density - as measured by Producer or at Truck Unload or Oil Analysis. | I14: Ref Price | J14: =J13+(J10+J12)*6.29287*J11 -> 643.79157 | K14: =K13+(K10+K12)*6.29287*K11 -> 635.97974 | L14: =L13+(L10+L12)*6.2898105*L11 -> 565.73896
A15: Condensate Density - as reported by CM or Plains or Producer/Customer deliveries in the delivery month. | E15: Apparent Condensate | F15: =F10-F11 -> 4967.3529 | I15: EQ | J15: =IF(J8>825,(825-J8)*0.49,IF(J8<800,(J8-800)*0.49,0))+(0.5-J9)*13.8 -> 2.07 | K15: =(750-K8)*$B$18+(0.2-$K$9)*13.8 -> 3.59 | L15: 0
A16: Target Blend Density - CHV density, as reported by CM or Plains or Producer/Customer, in the delivery month | E16: Shrinkage as: %C5+ | F16: =F11/F10*100 -> 1.9370174 | I16: Tariff on Purchase
E17: Shrinkage as: %Blend | F17: =(F19-F12)/F19*100 -> 0.3743221 | I17: Trucking on Purchase
A18: C5 Density Slope | B18: =_xlfn.XLOOKUP($B$8,MonthlyData!$B:$B,MonthlyData!$Y:$Y) -> 0.17 | E18: Shrinkage as: % Shrunk Blend | F18: =(F19-F12)/F12*100 -> 0.37572853 | I18: Other
A19: Rainbow Interface % | B19: 0.0197 | E19: vol blend w/o shrinkage | F19: =F8+F10 -> 26212.472 | I19: Netback | J19: =SUM(J14:J18) -> 645.86157 | K19: =SUM(K14:K18) -> 639.56974 | L19: =SUM(L14:L18) -> 565.73896
E20: C5+ as % of dry crude | F20: =F10/F8*100 -> 23.95362
E21: C5+ as % of blend | F21: =F10/F12*100 -> 19.397272
A24: NovaCor Eqn
A25: ITERATIONS: | D25: vol C5+ | E25: Density Blend
A26: % C5+ in Total Blend (Fc) = | B26: =((B10-B12)/(B10-B11))*100 -> 17.807018 | C26: % | D26: =(B26/100*$B$9)/(1-B26/100) -> 4581.4739 | E26: =(D26*$B$11+$B$9*$B$10)/(D26+$B$9)/(1-B27/100) -> 927.68764
A27: Blend Shrinkage Factor (Sf) = | B27: =(0.0266*B26)-(0.0004*(POWER(B26,2)))+(0.000001339*(POWER(B26,3))) -> 0.35439128 | C27: % | D27: =(B9/(1-B26/100))*(B26/100) -> 4581.4739
A28: % C5+ in Total Blend (Fc) = | B28: =(((($B$10-$B$12)/($B$10-$B$11))+((B27/100)*$B$12)/($B$10-$B$11)))*100 -> 19.243857 | C28: % | D28: =(B28/100*$B$9)/(1-B28/100) -> 5039.2431 | E28: =(D28*$B$11+$B$9*$B$10)/(D28+$B$9)/(1-B29/100) -> 924.57543
A29: Blend Shrinkage Factor (Sf) = | B29: =(0.0266*B28)-(0.0004*(POWER(B28,2)))+(0.000001339*(POWER(B28,3))) -> 0.37329856 | C29: %
A30: % C5+ in Total Blend (Fc) = | B30: =(((($B$10-$B$12)/($B$10-$B$11))+((B29/100)*$B$12)/($B$10-$B$11)))*100 -> 19.320514 | C30: % | D30: =(B30/100*$B$9)/(1-B30/100) -> 5064.1239 | E30: =(D30*$B$11+$B$9*$B$10)/(D30+$B$9)/(1-B31/100) -> 924.40901
A31: Blend Shrinkage Factor (Sf) = | B31: =(0.0266*B30)-(0.0004*(POWER(B30,2)))+(0.000001339*(POWER(B30,3))) -> 0.37426964 | C31: %
A32: % C5+ in Total Blend (Fc) = | B32: =(((($B$10-$B$12)/($B$10-$B$11))+((B31/100)*$B$12)/($B$10-$B$11)))*100 -> 19.324451 | C32: % | D32: =(B32/100*$B$9)/(1-B32/100) -> 5065.403 | E32: =(D32*$B$11+$B$9*$B$10)/(D32+$B$9)/(1-B33/100) -> 924.40046
A33: Blend Shrinkage Factor (Sf) = | B33: =(0.0266*B32)-(0.0004*(POWER(B32,2)))+(0.000001339*(POWER(B32,3))) -> 0.37431942 | C33: %
A34: % C5+ in Total Blend (Fc) = | B34: =(((($B$10-$B$12)/($B$10-$B$11))+((B33/100)*$B$12)/($B$10-$B$11)))*100 -> 19.324653 | C34: % | D34: =(B34/100*$B$9)/(1-B34/100) -> 5065.4686 | E34: =(D34*$B$11+$B$9*$B$10)/(D34+$B$9)/(1-B35/100) -> 924.40002
A35: Blend Shrinkage Factor (Sf) = | B35: =(0.0266*B34)-(0.0004*(POWER(B34,2)))+(0.000001339*(POWER(B34,3))) -> 0.37432197 | C35: %
A36: % C5+ in Total Blend (Fc) = | B36: =(((($B$10-$B$12)/($B$10-$B$11))+((B35/100)*$B$12)/($B$10-$B$11)))*100 -> 19.324663 | C36: % | D36: =(B36/100*$B$9)/(1-B36/100) -> 5065.4719 | E36: =(D36*$B$11+$B$9*$B$10)/(D36+$B$9)/(1-B37/100) -> 924.4
A37: Blend Shrinkage Factor (Sf) = | B37: =(0.0266*B36)-(0.0004*(POWER(B36,2)))+(0.000001339*(POWER(B36,3))) -> 0.3743221 | C37: %
A39: Pricing | E39: =1/1.3378 -> 0.74749589
A41: Condensate price @ Edmonton | B41: =$K$19 -> 639.56974 | C41: CAD/M3
A42: C5 RP2 Edm-Nipisi Toll: | B42: 16.54 | C42: CAD/M3
A43: C5 ENB/PMC Terminalling | B43: 3.47 | C43: CAD/M3
A44: Total Condensate price: | B44: =SUM(B41:B43) -> 659.57974 | C44: CAD/M3
A46: CHV Price (Edmonton) | B46: =$L$19 -> 565.73896 | C46: CAD/M3
A47: Rainbow Pipeline Terminal Fee | B47: 0 | C47: CAD/M3
A48: Rainbow Pipeline Tariff | B48: -11.82 | C48: CAD/M3
A49: Rainbow Inferface Fee | B49: =($L$19-$J$19)*$B$19 -> -1.5784156 | C49: CAD/M3
A50: Heavy Blend in Rainbow Nipisi Storage | B50: =SUM(B46:B49) -> 552.34054 | C50: CAD/M3
...

Sheet KINGMitsueTT Dil Fee Nipisi
A1: Diluent Optimization Benefit - ESTIMATED (NO CRUDE VISCOSITY DATA)
A4: PRICING ASSUMPTIONS: | C4: WADF | D4: PAR | E4: STREAM
A5: MONTH: | B5: ='Spur-Netback'!C37 -> 45413 | C5: $Cdn/m3 | D5: $Cdn/m3 | E5: $Cdn/m3 | G5: =B5 -> 45413 | H5: CONDENSATE EQ: | I5: $/m3 | J5: C4 Content | K5: Penalty $/m3 | L5: Penalty $/m3 /.1%
A6: WTI: | B6: =_xlfn.XLOOKUP($B$5,MonthlyData!$B:$B,MonthlyData!$D:$D) -> 78.62 | H6: C5+ Allow Price | I6: =_xlfn.XLOOKUP($B$5,MonthlyData!$B:$B,MonthlyData!$Z:$Z) -> 636.91 | J6: <=5.0% | K6: 0 | L6: 0
A7: FX: | B7: =_xlfn.XLOOKUP($B$5,MonthlyData!$B:$B,MonthlyData!$E:$E) -> 1.36695 | H7: Butane Price | I7: 0 | J7: >5.0%-7.0% | K7: =ROUND(I6-I8,2) -> 636.91 | L7: =ROUND(K7/1000,6) -> 0.63691
A8: CHV INDEX ($US/bbl): | B8: =_xlfn.XLOOKUP($B$5,MonthlyData!$B:$B,MonthlyData!$BP:$BP) -> -12.82 | E8: =(B6+B8)*6.2898105*B7 -> 565.73896 | H8: 50% of Butane Value | I8: =ROUND(I7/2,2) -> 0 | J8: > 7.0% | K8: =ROUND(I6,2) -> 636.91 | L8: =ROUND(K8/1000,6) -> 0.63691
A9: C5+ INDEX ($US/bbl): | B9: =_xlfn.XLOOKUP($B$5,MonthlyData!$B:$B,MonthlyData!$M:$M) -> -4.19 | C9: =_xlfn.XLOOKUP($B$5,MonthlyData!$B:$B,MonthlyData!$X:$X) -> -4.27 | D9: =(($B$6+B9)*6.29287*$B$7)+C9 -> 635.97974 | E9: =D9-C9 -> 640.24974 | H9: Density Slope (C5+) | I9: =_xlfn.XLOOKUP($B$5,MonthlyData!$B:$B,MonthlyData!$Y:$Y) -> 0.17 | J9: $ / m3 per kg / m3 | L9: 750 kg/m3
A10: C4 Price %WTI (Landed): | B10: =_xlfn.XLOOKUP($B$5,MonthlyData!$B:$B,MonthlyData!$AM:$AM) -> 0.475 | E10: =(B6*B10)*6.29287*B7+D10 -> 321.23883 | H10: Sulphur | I10: =I13 -> 1.38 | J10: $ / m3 per .1 wt% | L10: .2% wt
A11: \ | B11: =B10 -> 0.475 | H11: CRUDE (INDUSTRY) EQ:
A12: C4 Diff: | B12: =1-B11 -> 0.525 | C12: (1 - 62.4%) | H12: Density Slope (Crude) | I12: 0.49 | J12: $ / m3 per kg / m3 | K12: Heavy Allow Price: | L12: =_xlfn.XLOOKUP($B$5,MonthlyData!$B:$B,MonthlyData!$AE:$AE) -> 0
A13: C4 Purchase Price ($US/bbl): | B13: =B6*B11 -> 37.3445 | H13: Sulphur | I13: 1.38 | J13: $ / m3 per .1 wt% | K13: Enb. Ref Temp: | L13: =_xlfn.XLOOKUP($B$5,MonthlyData!$B:$B,MonthlyData!$AF:$AF) -> 0
A14: C4 Diff to WTI ($US/bbl): | B14: =B13-B6 -> -41.2755 | D14: C4 vs. C5+: | E14: =E10-I15 -> -337.06883 | H14: Calculated EQ CREDIT: | I14: =(750-$L$14)*$I$9+(0.2-$L$15)*$I$10*10 -> 18.05793 | K14: C5+ Density: | L14: =Inputs!C7 -> 660
H15: C5+ Price after EQ: | I15: =E9+I14 -> 658.30767 | K15: C5+ Sulfur: | L15: =Inputs!C8 -> 0.00015
A18: Condensate Only - Paper Blend | N18: SCENARIO #1 - IF C5+ ONLY:
A19: API 12.3 Sec.5.3
B20: TEMP CORR. VOLUMES & DENSITY INPUTS | H20: RESULTS | O20: Value | R20: Result
B21: m3 | C21: Dens @ 15C | D21: % of Blend | H21: Shrinkage Percent | I21: SHRINKAGE | J21: Sum of Volumes | K21: Resultant Volume | N21: Raw Heavy Volume | O21: =B22 -> 21147 | Q21: Raw (m3) | R21: =O32 -> 21147
A22: RAW CRUDE OIL: | B22: =Inputs!C5 -> 21147 | C22: =Inputs!C16 -> 965 | D22: =B22/B26 -> 0.86688525 | H22: % | I22: m3 | N22: Raw Heavy Density | O22: =C22 -> 965 | Q22: C5 (m3) | R22: =SUM(O34:S34) -> 3666.2356
A23: Butane: | B23: 0 | C23: 575 | D23: =B23/B26 -> 0 | H23: =IFERROR(26900*F36*(100-F36)^0.819*(I36-J36)^2.28,0) -> 0 | I23: =IFERROR(H23/100*(B36+D36),0) -> 0 | J23: =B36+D36 -> 21147 | K23: =B36+D36-I23 -> 21147 | N23: C5 Density | O23: =C24 -> 660 | Q23: Delivered (m3) | R23: =S40 -> 24693.378
A24: Condensate: | B24: =(C22-B28)/(B28-C24)*B22 -> 3247.2322 | C24: =L14 -> 660 | D24: =B24/B26 -> 0.13311475 | H24: =IFERROR(26900*F37*(100-F37)^0.819*(I37-J37)^2.28,0) -> 0.3733277 | I24: =IFERROR(H24/100*(B37+D37),0) -> 91.070427 | J24: =B37+D37 -> 24394.232 | K24: =B37+D37-I24 -> 24303.162 | N24: Target Density | O24: =B28 -> 924.4 | Q24: Shrinkage (m3) | R24: =R23-SUM(R21:R22) -> -119.8572
H25: =IFERROR(26900*F38*(100-F38)^0.819*(I38-J38)^2.28,0) -> 0 | I25: =IFERROR(H25/100*(B38+D38),0) -> 0 | J25: =B38+D38 -> 24303.162 | K25: =B38+D38-I25 -> 24303.162
A26: Total Receipts: | B26: =SUM(B22:B25) -> 24394.232 | D26: =SUM(D22:D25) -> 1 | H26: =IF(I26=0,"",(I26/K26)) -> 0.0037472666 | I26: =(SUM(I23:I25))*1 -> 91.070427 | K26: =K25 -> 24303.162 | N26: API 12.3 Heavy Oil Adjusted
A27: Wt.Avg. Kg/m3: | B27: =SUMPRODUCT(B22:B25,C22:C25)/SUM(B22:B25) -> 924.4 | J27: Total Receipts: | K27: =B26 -> 24394.232 | O27: Iteration 1 | P27: Iteration 2 | Q27: Iteration 3 | R27: Iteration 4 | S27: Iteration 5
A28: Target Density | B28: =Inputs!C18 -> 924.4 | J28: Total Shrinkage: | K28: =I26*-1 -> -91.070427 | N28: Target Density | O28: =$B$28 -> 924.4 | P28: =O28 -> 924.4 | Q28: =P28 -> 924.4 | R28: =Q28 -> 924.4 | S28: =R28 -> 924.4
B29: =D49 -> 924.4 | J29: Net Volume: | K29: =K27+K28 -> 24303.162 | N29: Diluent Density | O29: =$C$24 -> 660 | P29: =O29 -> 660 | Q29: =P29 -> 660 | R29: =Q29 -> 660 | S29: =R29 -> 660
J30: Total Shrinkage as % of Total Receipts: | K30: =I26/B26 -> 0.003733277 | N30: Raw Crude Density | O30: =$C$22 -> 965 | P30: =O41 -> 928.48481 | Q30: =P41 -> 924.82147 | R30: =Q41 -> 924.44359 | S30: =R41 -> 924.40451
A31: API 12.3 Sec.5.3
A32: --- Linked to INPUT values above --- | N32: Raw Heavy Volume (m3) | O32: =$B$22 -> 21147 | P32: =O40 -> 24286.911 | Q32: =P40 -> 24650.889 | R32: =Q40 -> 24689.02 | S32: =R40 -> 24692.97
B33: LIGHT | D33: RAW CRUDE OIL | N33: Raw Heavy Mass (kg) | O33: =O32*O30 -> 20406855 | P33: =P32*P30 -> 22550028 | Q33: =Q32*Q30 -> 22797672 | R33: =R32*R30 -> 22823606 | S33: =S32*S30 -> 22826293
B34: Diluent Volume | C34: Average Density | D34: Volume | E34: Average Density | F34: X = DILUENT Volume/(Crude Volume + DILUENT Volume) | G34: XX = CRUDE Volume/(CRUDE Volume + Diluent Volume) | H34: CRUDE + DILUENT BLEND | I34: 1/dL | J34: 1/dH | N34: Diluent Required (m3) | O34: =(O28*O32-O30*O32)/(O29-O28) -> 3247.2322 | P34: =(P28*P32-P30*P32)/(P29-P28) -> 375.21729 | Q34: =(Q28*Q32-Q30*Q32)/(Q29-Q28) -> 39.295037 | R34: =(R28*R32-R30*R32)/(R29-R28) -> 4.0699587 | S34: =(S28*S32-S30*S32)/(S29-S28) -> 0.42105704
B35: m3 | C35: kg/m3 | D35: m3 | E35: kg/m3 | F35: % | G35: % | H35: % | N35: Diluent Mass (kg) | O35: =O34*O29 -> 2143173.3 | P35: =P34*P29 -> 247643.41 | Q35: =Q34*Q29 -> 25934.725 | R35: =R34*R29 -> 2686.1728 | S35: =S34*S29 -> 277.89765
A36: Butane: | B36: =B23 -> 0 | C36: =C23 -> 575 | D36: =B22 -> 21147 | E36: =C22 -> 965 | F36: =IFERROR(B36/(B36+D36)*100,"") -> 0 | G36: =IFERROR(D36/(B36+D36)*100,"") -> 100 | H36: =F36+G36 -> 100 | I36: =IFERROR(1/C36,"") -> 0.0017391304 | J36: =IFERROR(1/E36,"") -> 0.0010362694
A37: Condensate: | B37: =B24 -> 3247.2322 | C37: =C24 -> 660 | D37: =K23 -> 21147 | E37: =E36 -> 965 | F37: =IFERROR(B37/(B37+D37)*100,"") -> 13.311475 | G37: =IFERROR(D37/(B37+D37)*100,"") -> 86.688525 | H37: =F37+G37 -> 100 | I37: =IFERROR(1/C37,"") -> 0.0015151515 | J37: =IFERROR(1/E37,"") -> 0.0010362694 | N37: Diluent as % of Blend | O37: =O34/(O32+O34) -> 0.13311475 | P37: =P34/(P32+P34) -> 0.015214311 | Q37: =Q34/(Q32+Q34) -> 0.0015915247 | R37: =R34/(R32+R34) -> 0.00016482177 | S37: =S34/(S32+S34) -> 1.7051406e-05
A38: OIL: | B38: =K24 -> 24303.162 | C38: =E37 -> 965 | D38: =B25 -> 0 | E38: =C25 -> 0 | F38: =IFERROR(B38/(B38+D38)*100,"") -> 100 | G38: =IFERROR(D38/(B38+D38)*100,"") -> 0 | H38: =F38+G38 -> 100 | I38: =IFERROR(1/C38,"") -> 0.0010362694 | J38: =IFERROR(1/E38,"") | N38: Shrinkage as % of Blend | O38: =31700*O37*(100-O37*100)^0.819*(1/O29-1/O30)^2.28 -> 0.004399438 | P38: =31700*P37*(100-P37*100)^0.819*(1/P29-1/P30)^2.28 -> 0.0004557311 | Q38: =31700*Q37*(100-Q37*100)^0.819*(1/Q29-1/Q30)^2.28 -> 4.7148425e-05 | R38: =31700*R37*(100-R37*100)^0.819*(1/R29-1/R30)^2.28 -> 4.87716e-06 | S38: =31700*S37*(100-S37*100)^0.819*(1/S29-1/S30)^2.28 -> 5.0449949e-07
A39: dL | B39: = Density of Light | N39: Shrinkage (m3) | O39: =-O38*(O32+O34) -> -107.32091 | P39: =-P38*(P32+P34) -> -11.239299 | Q39: =-Q38*(Q32+Q34) -> -1.1641033 | R39: =-R38*(R32+R34) -> -0.12043215 | S39: =-S38*(S32+S34) -> -0.012457803
A40: dH | B40: = Density of Heavy | N40: Volume After Shrinkage | O40: =O32+O34+O39 -> 24286.911 | P40: =P32+P34+P39 -> 24650.889 | Q40: =Q32+Q34+Q39 -> 24689.02 | R40: =R32+R34+R39 -> 24692.97 | S40: =S32+S34+S39 -> 24693.378
A41: X | B41: = % concentraion of Diluent. (i.e., Diluent percentage of total blend). | N41: Density After Shrinkage | O41: =(O33+O35)/O40 -> 928.48481 | P41: =(P33+P35)/P40 -> 924.82147 | Q41: =(Q33+Q35)/Q40 -> 924.44359 | R41: =(R33+R35)/R40 -> 924.40451 | S41: =(S33+S35)/S40 -> 924.40047
A42: XX | B42: = % concentraion of Crude. (i.e., Crude percentage of total blend).
A44: Condensate Only - Net Sales Calculation | N44: SCENARIO #1 - FINANCIAL RESULTS:
C45: m3 | D45: kg/m3 | E45: % Inject | F45: % of Blend | P45: m3 | Q45: kg/m3 | R45: % Inject | S45: % of Blend
...

Sheet Gibsons Novacor Edm
A3: NOVACOR: Condensate Addition & Shrinkage Calculations
F7: RESULTS | K7: CRW C5+ | L7: CHV
A8: Date | B8: ='Spur-Netback'!C37 -> 45413 | E8: Volume of Dry Crude = | F8: =B9 -> 21147 | G8: m3 | I8: Density (KG/M3) | K8: =Inputs!C13 -> 730 | L8: =Inputs!C18 -> 924.4
A9: Volume of Raw Crude = | B9: =Inputs!C5 -> 21147 | C9: M3 | E9: % C5+ in Total Blend (Fc) = | F9: =B36 -> 18.718424 | G9: % | I9: Sulfur (%Swt) | K9: 0.1 | L9: 4
A10: Density of Raw Crude = | B10: =Inputs!C16 -> 965 | C10: KG/M3 | E10: Condensate Required in Blend= | F10: =((F9/100)*B9)/(1-F9/100) -> 4869.966 | G10: m3 | I10: WTI (USD/BBL) | K10: =_xlfn.XLOOKUP($B$8,MonthlyData!$B:$B,MonthlyData!$D:$D) -> 78.62 | L10: =_xlfn.XLOOKUP($B$8,MonthlyData!$B:$B,MonthlyData!$D:$D) -> 78.62
A11: Density of Condensate (CRW C5+) = | B11: =K8 -> 730 | C11: KG/M3 | E11: Shrinkage Volume = | F11: =(B9+F10)*B37/100 -> 95.362644 | G11: m3 | I11: FX (CAD/USD) | K11: =_xlfn.XLOOKUP($B$8,MonthlyData!$B:$B,MonthlyData!$E:$E) -> 1.36695 | L11: =_xlfn.XLOOKUP($B$8,MonthlyData!$B:$B,MonthlyData!$E:$E) -> 1.36695
A12: Density of Target Blend = | B12: =L8 -> 924.4 | C12: KG/M3 | E12: Volume of Blend = | F12: =B9+F10-F11 -> 25921.603 | G12: m3 | I12: Diff (USD/BBL) | K12: =_xlfn.XLOOKUP($B$8,MonthlyData!$B:$B,MonthlyData!$M:$M) -> -4.19 | L12: =_xlfn.XLOOKUP($B$8,MonthlyData!$B:$B,MonthlyData!$BP:$BP) -> -12.82
I13: WADF (CAD/M3) | K13: =_xlfn.XLOOKUP($B$8,MonthlyData!$B:$B,MonthlyData!$X:$X) -> -4.27 | L13: 0
A14: Raw Crude Density - as measured by Producer or at Truck Unload or Oil Analysis. | I14: Ref Price | K14: =K13+(K10+K12)*6.29287*K11 -> 635.97974 | L14: =L13+(L10+L12)*6.2898105*L11 -> 565.73896
A15: Condensate Density - as reported by CM or Plains or Producer/Customer deliveries in the delivery month. | E15: Apparent Condensate | F15: =F10-F11 -> 4774.6034 | I15: EQ | K15: =(750-K8)*$B$18+(0.2-$K$9)*13.8 -> 4.78 | L15: 0
A16: Target Blend Density - CHV density, as reported by CM or Plains or Producer/Customer, in the delivery month | E16: Shrinkage as: %C5+ | F16: =F11/F10*100 -> 1.9581788 | I16: Tariff on Purchase
E17: Shrinkage as: %Blend | F17: =(F19-F12)/F19*100 -> 0.36654022 | I17: Trucking on Purchase
A18: C5 Density Slope | B18: =_xlfn.XLOOKUP($B$8,MonthlyData!$B:$B,MonthlyData!$Y:$Y) -> 0.17 | E18: Shrinkage as: % Shrunk Blend | F18: =(F19-F12)/F12*100 -> 0.36788868 | I18: Other
A19: Rainbow Interface % | B19: 0 | E19: vol blend w/o shrinkage | F19: =F8+F10 -> 26016.966 | I19: Netback | K19: =SUM(K14:K18) -> 640.75974 | L19: =SUM(L14:L18) -> 565.73896
E20: C5+ as % of dry crude | F20: =F10/F8*100 -> 23.029111
E21: C5+ as % of blend | F21: =F10/F12*100 -> 18.787287
A24: NovaCor Eqn
A25: ITERATIONS: | D25: vol C5+ | E25: Density Blend
A26: % C5+ in Total Blend (Fc) = | B26: =((B10-B12)/(B10-B11))*100 -> 17.276596 | C26: % | D26: =(B26/100*$B$9)/(1-B26/100) -> 4416.5031 | E26: =(D26*$B$11+$B$9*$B$10)/(D26+$B$9)/(1-B27/100) -> 927.61949
A27: Blend Shrinkage Factor (Sf) = | B27: =(0.0266*B26)-(0.0004*(POWER(B26,2)))+(0.000001339*(POWER(B26,3))) -> 0.34707001 | C27: % | D27: =(B9/(1-B26/100))*(B26/100) -> 4416.5031
A28: % C5+ in Total Blend (Fc) = | B28: =(((($B$10-$B$12)/($B$10-$B$11))+((B27/100)*$B$12)/($B$10-$B$11)))*100 -> 18.641836 | C28: % | D28: =(B28/100*$B$9)/(1-B28/100) -> 4845.4745 | E28: =(D28*$B$11+$B$9*$B$10)/(D28+$B$9)/(1-B29/100) -> 924.57136
A29: Blend Shrinkage Factor (Sf) = | B29: =(0.0266*B28)-(0.0004*(POWER(B28,2)))+(0.000001339*(POWER(B28,3))) -> 0.36554016 | C29: %
A30: % C5+ in Total Blend (Fc) = | B30: =(((($B$10-$B$12)/($B$10-$B$11))+((B29/100)*$B$12)/($B$10-$B$11)))*100 -> 18.714491 | C30: % | D30: =(B30/100*$B$9)/(1-B30/100) -> 4868.7071 | E30: =(D30*$B$11+$B$9*$B$10)/(D30+$B$9)/(1-B31/100) -> 924.4088
A31: Blend Shrinkage Factor (Sf) = | B31: =(0.0266*B30)-(0.0004*(POWER(B30,2)))+(0.000001339*(POWER(B30,3))) -> 0.36648895 | C31: %
A32: % C5+ in Total Blend (Fc) = | B32: =(((($B$10-$B$12)/($B$10-$B$11))+((B31/100)*$B$12)/($B$10-$B$11)))*100 -> 18.718223 | C32: % | D32: =(B32/100*$B$9)/(1-B32/100) -> 4869.9016 | E32: =(D32*$B$11+$B$9*$B$10)/(D32+$B$9)/(1-B33/100) -> 924.40045
A33: Blend Shrinkage Factor (Sf) = | B33: =(0.0266*B32)-(0.0004*(POWER(B32,2)))+(0.000001339*(POWER(B32,3))) -> 0.3665376 | C33: %
A34: % C5+ in Total Blend (Fc) = | B34: =(((($B$10-$B$12)/($B$10-$B$11))+((B33/100)*$B$12)/($B$10-$B$11)))*100 -> 18.718414 | C34: % | D34: =(B34/100*$B$9)/(1-B34/100) -> 4869.9629 | E34: =(D34*$B$11+$B$9*$B$10)/(D34+$B$9)/(1-B35/100) -> 924.40002
A35: Blend Shrinkage Factor (Sf) = | B35: =(0.0266*B34)-(0.0004*(POWER(B34,2)))+(0.000001339*(POWER(B34,3))) -> 0.36654009 | C35: %
A36: % C5+ in Total Blend (Fc) = | B36: =(((($B$10-$B$12)/($B$10-$B$11))+((B35/100)*$B$12)/($B$10-$B$11)))*100 -> 18.718424 | C36: % | D36: =(B36/100*$B$9)/(1-B36/100) -> 4869.966 | E36: =(D36*$B$11+$B$9*$B$10)/(D36+$B$9)/(1-B37/100) -> 924.4
A37: Blend Shrinkage Factor (Sf) = | B37: =(0.0266*B36)-(0.0004*(POWER(B36,2)))+(0.000001339*(POWER(B36,3))) -> 0.36654022 | C37: %
A39: Pricing | E39: =1/1.3378 -> 0.74749589
A41: Condensate price @ Edmonton | B41: =$K$19 -> 640.75974 | C41: CAD/M3
A42: Gibsons P/L Toll | B42: 2 | C42: CAD/M3
A43: C5 ENB Terminalling | B43: 3.39 | C43: CAD/M3
A44: Total Condensate price: | B44: =SUM(B41:B43) -> 646.14974 | C44: CAD/M3
A46: CHV Price (Edmonton) | B46: =$L$19 -> 565.73896 | C46: CAD/M3
A47: Pipeline Terminal Fee | B47: 0 | C47: CAD/M3
A48: Pipeline Tariff | B48: 0 | C48: CAD/M3
A49: Storage Fee | B49: 0 | C49: CAD/M3
A50: Heavy Blend in Gibsons Storage | B50: =SUM(B46:B49) -> 565.73896 | C50: CAD/M3
...

Sheet FlintHills Novacor Hardisty
A3: NOVACOR: Condensate Addition & Shrinkage Calculations
F7: RESULTS | K7: CRW C5+ | L7: WCS
A8: Date | B8: ='Spur-Netback'!C37 -> 45413 | E8: Volume of Dry Crude = | F8: =B9 -> 21147 | G8: m3 | I8: Density (KG/M3) | K8: =Inputs!C13 -> 730 | L8: =_xlfn.XLOOKUP($B$8,MonthlyData!$B:$B,MonthlyData!$AD:$AD) -> 924.8
A9: Volume of Raw Crude = | B9: =Inputs!C5 -> 21147 | C9: M3 | E9: % C5+ in Total Blend (Fc) = | F9: =B36 -> 18.539624 | G9: % | I9: Sulfur (%Swt) | K9: 0.1 | L9: 4
